<?xml version="1.0"?>
<robot name="hexapod">

    <gazebo>
        <plugin name="gazebo_ros_control" filename="libgazebo_ros_control.so">
            <robotNamespace>/hexapod</robotNamespace>
            <parameters>$(find hex)/config/hexapod.yaml</parameters>
        </plugin>
    </gazebo>


    <link name="base">
        <visual>
            <geometry>
                <mesh filename="package://hex/models/hexapod/meshes/base/base.stl" scale="0.8 0.8 1.8"/>
            </geometry>
            <origin xyz="0.0 0 0"/>
            <material name="red">
                <color rgba="0.5 0 0.2 1"/>
            </material>
        </visual>
        <inertial>
            <mass value="2"/>
            <inertia ixx="0.04" ixy="0.0" ixz="0.0" iyy="0.17" iyz="0.0" izz="0.25"/>
        </inertial>    
        <collision>
            <geometry>
                <mesh filename="package://hex/models/hexapod/meshes/base/base.stl" scale="0.8 0.8 1.8"/>
            <origin xyz="0.0 0.0 0"/>
            </geometry>
        </collision>
    </link>
    <gazebo reference="base">
        <kp>1000.0</kp>
        <kd>1000.0</kd>
        <mu1>0.5</mu1>
        <mu2>0.5</mu2>
        <material>Gazebo/Red</material>
    </gazebo>


<!--Leg front left-->

    <link name="hipassembly_1">
	    <visual>
	      <origin rpy="0.0 0.0 0.0" xyz="0.0 0.0 0.0"/>
	      <geometry>
	        <mesh filename="package://hex/models/hexapod/meshes/leg/assembler.stl" scale="1 1 1"/>
	      </geometry>
            <material name="green">
                <color rgba="0 0.6 0 1"/>
            </material>
	    </visual>
        <collision>
            <origin rpy="0.0 0.0 0.0" xyz="0.0 0.0 0.0"/>
	        <geometry>
	            <mesh filename="package://hex/models/hexapod/meshes/leg/assembler.stl" scale="1 1 1"/>
	        </geometry> 
        </collision>   
        <inertial>
            <mass value="2"/>
            <inertia ixx="0.04" ixy="0.0" ixz="0.0" iyy="0.17" iyz="0.0" izz="0.25"/>
        </inertial>  
    </link>

    <gazebo reference="hipassembly_1">
        <kp>1000.0</kp>
        <kd>1000.0</kd>
        <mu1>0.5</mu1>
        <mu2>0.5</mu2>
        <material>Gazebo/Green</material>
    </gazebo>

    <link name="upperleg_1">
	    <visual>
	      <origin rpy="0.0 0.0 0.0" xyz="0.0 0.0 0.0"/>
	      <geometry>
	        <mesh filename="package://hex/models/hexapod/meshes/leg/upperleg.stl" scale="0.8 1 1"/>
	      </geometry>
            <material name="orange">
                <color rgba="0.8 0.5 0 1"/>
            </material>	  
	    </visual>
        <collision>
            <origin rpy="0.0 0.0 0.0" xyz="0.0 0.0 0.0"/>
	        <geometry>
	            <mesh filename="package://hex/models/hexapod/meshes/leg/upperleg.stl" scale="0.8 1 1"/>
	        </geometry> 
        </collision>   
        <inertial>
            <mass value="2"/>
            <inertia ixx="0.04" ixy="0.0" ixz="0.0" iyy="0.17" iyz="0.0" izz="0.25"/>
        </inertial>  
    </link>

    <gazebo reference="upperleg_1">
        <kp>1000.0</kp>
        <kd>1000.0</kd>
        <mu1>0.5</mu1>
        <mu2>0.5</mu2>
        <material>Gazebo/Orange</material>
    </gazebo>


    <link name="lowerleg_1">
	    <visual>
	      <geometry>
	        <mesh filename="package://hex/models/hexapod/meshes/leg/lowerleg.stl" scale="1.4 1 1"/>
	      </geometry>
            <material name="blue">
                <color rgba="0 0 0.5 1"/>
            </material>	  
        </visual>       
         <collision>
            <origin rpy="0.0 0.0 0.0" xyz="0.0 0.0 0.0"/>
	        <geometry>
	            <mesh filename="package://hex/models/hexapod/meshes/leg/lowerleg.stl" scale="1.4 1 1"/>
	        </geometry> 
        </collision>   
        <inertial>
            <mass value="2"/>
            <inertia ixx="0.04" ixy="0.0" ixz="0.0" iyy="0.17" iyz="0.0" izz="0.25"/>
        </inertial>  
    </link>


    <gazebo reference="lowerleg_1">
        <kp>1000.0</kp>
        <kd>1000.0</kd>
        <mu1>0.5</mu1>
        <mu2>0.5</mu2>
        <material>Gazebo/Blue</material>
    </gazebo>

    <joint name="haa_joint_1" type="revolute">
        <origin xyz="0.65 0.45 0.03" rpy="0 0 0"/>
        <parent link="base"/>
        <child  link="hipassembly_1"/>
        <limit effort="2000" lower="0" upper="2.27" velocity="1.0"/>
        <axis xyz="0 0 1"/>
    </joint>

    <transmission name="haa_joint_1_trans">
        <type>transmission_interface/SimpleTransmission</type>
        <joint name="haa_joint_1">
            <hardwareInterface>hardware_interface/EffortJointInterface</hardwareInterface>
        </joint>
        <actuator name="haa_joint_1_Motor">
        <hardwareInterface>hardware_interface/EffortJointInterface</hardwareInterface>
        <mechanicalReduction>1</mechanicalReduction>
        </actuator>
    </transmission>

    <joint name="hfe_joint_1" type="revolute">
        <origin xyz="0.08000 0.00000 0.00000" rpy="1.5707963705062866 0 0.0"/>
        <parent link="hipassembly_1"/>
        <child  link="upperleg_1"/>
        <limit effort="2000" lower="0.3" upper="1.4" velocity="1.0"/>
        <axis xyz="0 0 1"/>
    </joint>

    <transmission name="hfe_joint_1_trans">
        <type>transmission_interface/SimpleTransmission</type>
        <joint name="hfe_joint_1">
            <hardwareInterface>hardware_interface/EffortJointInterface</hardwareInterface>
        </joint>
        <actuator name="hfe_joint_1_Motor">
        <hardwareInterface>hardware_interface/EffortJointInterface</hardwareInterface>
        <mechanicalReduction>1</mechanicalReduction>
        </actuator>
    </transmission>


    <joint name="kfe_joint_1" type="revolute">
        <origin xyz="0.27000 0.0000 0.0000" rpy="0.0 0.0 0.0"/>
        <parent link="upperleg_1"/>
        <child  link="lowerleg_1"/>
        <limit effort="2000" lower="-2.27" upper="-1.57" velocity="1.0"/>
        <axis xyz="0 0 1"/>
    </joint>

    <transmission name="kfe_joint_1_trans">
        <type>transmission_interface/SimpleTransmission</type>
        <joint name="kfe_joint_1">
            <hardwareInterface>hardware_interface/EffortJointInterface</hardwareInterface>
        </joint>
        <actuator name="kfe_joint_1_Motor">
        <hardwareInterface>hardware_interface/EffortJointInterface</hardwareInterface>
        <mechanicalReduction>1</mechanicalReduction>
        </actuator>
    </transmission>

<!--Leg middle left-->

    <link name="hipassembly_2">
	    <visual>
	      <origin rpy="0.0 0.0 0.0" xyz="0.0 0.0 0.0"/>
	      <geometry>
	        <mesh filename="package://hex/models/hexapod/meshes/leg/assembler.stl" scale="1 1 1"/>
	      </geometry>
            <material name="green">
                <color rgba="0 0.6 0 1"/>
            </material>
	    </visual> 
         <collision>
            <origin rpy="0.0 0.0 0.0" xyz="0.0 0.0 0.0"/>
	        <geometry>
	            <mesh filename="package://hex/models/hexapod/meshes/leg/assembler.stl" scale="1 1 1"/>
	        </geometry> 
        </collision>   
        <inertial>
            <mass value="0.2"/>
            <inertia ixx="0.04" ixy="0.0" ixz="0.0" iyy="0.17" iyz="0.0" izz="0.25"/>
        </inertial>         
    </link>


    <gazebo reference="hipassembly_2">
        <kp>1000.0</kp>
        <kd>1000.0</kd>
        <mu1>0.5</mu1>
        <mu2>0.5</mu2>
        <material>Gazebo/Green</material>
    </gazebo>


    <link name="upperleg_2">
	    <visual>
	      <origin rpy="0.0 0.0 0.0" xyz="0.0 0.0 0.0"/>
	      <geometry>
	            <mesh filename="package://hex/models/hexapod/meshes/leg/upperleg.stl" scale="0.8 1 1"/>
	      </geometry>
            <material name="orange">
                <color rgba="0.8 0.5 0 1"/>
            </material>	  
	    </visual>
         <collision>
            <origin rpy="0.0 0.0 0.0" xyz="0.0 0.0 0.0"/>
	        <geometry>
	            <mesh filename="package://hex/models/hexapod/meshes/leg/upperleg.stl" scale="0.8 1 1"/>
	        </geometry> 
        </collision>   
        <inertial>
            <mass value="2"/>
            <inertia ixx="0.04" ixy="0.0" ixz="0.0" iyy="0.17" iyz="0.0" izz="0.25"/>
        </inertial>  
    </link>

    <gazebo reference="upperleg_2">
        <kp>1000.0</kp>
        <kd>1000.0</kd>
        <mu1>0.5</mu1>
        <mu2>0.5</mu2>
        <material>Gazebo/Orange</material>
    </gazebo>

    <link name="lowerleg_2">
	    <visual>
	      <geometry>
	            <mesh filename="package://hex/models/hexapod/meshes/leg/lowerleg.stl" scale="1.4 1 1"/>
	      </geometry>
            <material name="blue">
                <color rgba="0 0 0.5 1"/>
            </material>	  
        </visual>    
         <collision>
            <origin rpy="0.0 0.0 0.0" xyz="0.0 0.0 0.0"/>
	        <geometry>
	            <mesh filename="package://hex/models/hexapod/meshes/leg/lowerleg.stl" scale="1.4 1 1"/>
	        </geometry> 
        </collision>   
        <inertial>
            <mass value="2"/>
            <inertia ixx="0.04" ixy="0.0" ixz="0.0" iyy="0.17" iyz="0.0" izz="0.25"/>
        </inertial>      
    </link>


    <gazebo reference="lowerleg_2">
        <kp>1000.0</kp>
        <kd>1000.0</kd>
        <mu1>0.5</mu1>
        <mu2>0.5</mu2>
        <material>Gazebo/Blue</material>
    </gazebo>

    <joint name="haa_joint_2" type="revolute">
        <origin xyz="0 0.45 0.03" rpy="0 0 0"/>
        <parent link="base"/>
        <child  link="hipassembly_2"/>
        <limit effort="200" lower="0.707" upper="2.27" velocity="1.0"/>
        <axis xyz="0 0 1"/>
    </joint>
    <joint name="hfe_joint_2" type="revolute">
        <origin xyz="0.08000 0.00000 0.00000" rpy="1.5707963705062866 0 0.0"/>
        <parent link="hipassembly_2"/>
        <child  link="upperleg_2"/>
        <limit effort="200" lower="0.3" upper="1.4" velocity="1.0"/>
        <axis xyz="0 0 1"/>
    </joint>
    <joint name="kfe_joint_2" type="revolute">
        <origin xyz="0.27000 0.0000 0.0000" rpy="0.0 0.0 0.0"/>
        <parent link="upperleg_2"/>
        <child  link="lowerleg_2"/>
        <limit effort="200" lower="-2.27" upper="-1.57" velocity="1.0"/>
        <axis xyz="0 0 1"/>
    </joint>

    <transmission name="haa_joint_2_trans">
        <type>transmission_interface/SimpleTransmission</type>
        <joint name="haa_joint_2">
            <hardwareInterface>hardware_interface/EffortJointInterface</hardwareInterface>
        </joint>
        <actuator name="haa_joint_2_Motor">
        <hardwareInterface>hardware_interface/EffortJointInterface</hardwareInterface>
        <mechanicalReduction>1</mechanicalReduction>
        </actuator>
    </transmission>

    <transmission name="hfe_joint_2_trans">
        <type>transmission_interface/SimpleTransmission</type>
        <joint name="hfe_joint_2">
            <hardwareInterface>hardware_interface/EffortJointInterface</hardwareInterface>
        </joint>
        <actuator name="hfe_joint_2_Motor">
        <hardwareInterface>hardware_interface/EffortJointInterface</hardwareInterface>
        <mechanicalReduction>1</mechanicalReduction>
        </actuator>
    </transmission>

    <transmission name="kfe_joint_2_trans">
        <type>transmission_interface/SimpleTransmission</type>
        <joint name="kfe_joint_2">
            <hardwareInterface>hardware_interface/EffortJointInterface</hardwareInterface>
        </joint>
        <actuator name="kfe_joint_2_Motor">
        <hardwareInterface>hardware_interface/EffortJointInterface</hardwareInterface>
        <mechanicalReduction>1</mechanicalReduction>
        </actuator>
    </transmission>



<!--Leg back left-->

    <link name="hipassembly_3">
	    <visual>
	      <origin rpy="0.0 0.0 0.0" xyz="0.0 0.0 0.0"/>
	      <geometry>
	        <mesh filename="package://hex/meshes/assembler.stl" scale="1 1 1"/>
	      </geometry>
            <material name="green">
                <color rgba="0 0.6 0 1"/>
            </material>
	    </visual>  
         <collision>
            <origin rpy="0.0 0.0 0.0" xyz="0.0 0.0 0.0"/>
	        <geometry>
	            <mesh filename="package://hex/models/hexapod/meshes/leg/assembler.stl" scale="1 1 1"/>
	        </geometry> 
        </collision>   
        <inertial>
            <mass value="2"/>
            <inertia ixx="0.04" ixy="0.0" ixz="0.0" iyy="0.17" iyz="0.0" izz="0.25"/>
        </inertial>           
    </link>

        <gazebo reference="hipassembly_3">
        <kp>1000.0</kp>
        <kd>1000.0</kd>
        <mu1>0.5</mu1>
        <mu2>0.5</mu2>
        <material>Gazebo/Green</material>
    </gazebo>

    <link name="upperleg_3">
	    <visual>
	      <origin rpy="0.0 0.0 0.0" xyz="0.0 0.0 0.0"/>
	      <geometry>
	            <mesh filename="package://hex/models/hexapod/meshes/leg/upperleg.stl" scale="0.8 1 1"/>
	      </geometry>
            <material name="orange">
                <color rgba="0.8 0.5 0 1"/>
            </material>	  
	    </visual>
         <collision>
            <origin rpy="0.0 0.0 0.0" xyz="0.0 0.0 0.0"/>
	        <geometry>
	            <mesh filename="package://hex/models/hexapod/meshes/leg/upperleg.stl" scale="0.8 1 1"/>
	        </geometry> 
        </collision>   
        <inertial>
            <mass value="2"/>
            <inertia ixx="0.04" ixy="0.0" ixz="0.0" iyy="0.17" iyz="0.0" izz="0.25"/>
        </inertial>     
    </link>

    <gazebo reference="upperleg_3">
        <kp>1000.0</kp>
        <kd>1000.0</kd>
        <mu1>0.5</mu1>
        <mu2>0.5</mu2>
        <material>Gazebo/Orange</material>
    </gazebo>

    <link name="lowerleg_3">
	    <visual>
	      <geometry>
	            <mesh filename="package://hex/models/hexapod/meshes/leg/lowerleg.stl" scale="1.4 1 1"/>
	      </geometry>
            <material name="blue">
                <color rgba="0 0 0.5 1"/>
            </material>	  
        </visual>  
         <collision>
            <origin rpy="0.0 0.0 0.0" xyz="0.0 0.0 0.0"/>
	        <geometry>
	            <mesh filename="package://hex/models/hexapod/meshes/leg/lowerleg.stl" scale="1.4 1 1"/>
	        </geometry> 
        </collision>   
        <inertial>
            <mass value="2"/>
            <inertia ixx="0.04" ixy="0.0" ixz="0.0" iyy="0.17" iyz="0.0" izz="0.25"/>
        </inertial>           
    </link>
 
    <gazebo reference="lowerleg_3">
        <kp>1000.0</kp>
        <kd>1000.0</kd>
        <mu1>0.5</mu1>
        <mu2>0.5</mu2>
        <material>Gazebo/Blue</material>
    </gazebo>
       
    <joint name="haa_joint_3" type="revolute">
        <origin xyz="-0.65 0.45 0.03" rpy="0 0 0"/>
        <parent link="base"/>
        <child  link="hipassembly_3"/>
        <limit effort="200" lower="0.707" upper="3.14" velocity="1.0"/>
        <axis xyz="0 0 1"/>
    </joint>
    <joint name="hfe_joint_3" type="revolute">
        <origin xyz="0.08000 0.00000 0.00000" rpy="1.5707963705062866 0 0.0"/>
        <parent link="hipassembly_3"/>
        <child  link="upperleg_3"/>
        <limit effort="200" lower="0.3" upper="1.4" velocity="1.0"/>
        <axis xyz="0 0 1"/>
    </joint>
    <joint name="kfe_joint_3" type="revolute">
        <origin xyz="0.27000 0.0000 0.0000" rpy="0.0 0.0 0.0"/>
        <parent link="upperleg_3"/>
        <child  link="lowerleg_3"/>
        <limit effort="200" lower="-2.27" upper="-1.57" velocity="1.0"/>
        <axis xyz="0 0 1"/>
    </joint>

    <transmission name="haa_joint_3_trans">
        <type>transmission_interface/SimpleTransmission</type>
        <joint name="haa_joint_3">
            <hardwareInterface>hardware_interface/EffortJointInterface</hardwareInterface>
        </joint>
        <actuator name="haa_joint_3_Motor">
        <hardwareInterface>hardware_interface/EffortJointInterface</hardwareInterface>
        <mechanicalReduction>1</mechanicalReduction>
        </actuator>
    </transmission>

    <transmission name="hfe_joint_3_trans">
        <type>transmission_interface/SimpleTransmission</type>
        <joint name="hfe_joint_3">
            <hardwareInterface>hardware_interface/EffortJointInterface</hardwareInterface>
        </joint>
        <actuator name="hfe_joint_3_Motor">
        <hardwareInterface>hardware_interface/EffortJointInterface</hardwareInterface>
        <mechanicalReduction>1</mechanicalReduction>
        </actuator>
    </transmission>

    <transmission name="kfe_joint_3_trans">
        <type>transmission_interface/SimpleTransmission</type>
        <joint name="kfe_joint_3">
            <hardwareInterface>hardware_interface/EffortJointInterface</hardwareInterface>
        </joint>
        <actuator name="kfe_joint_3_Motor">
        <hardwareInterface>hardware_interface/EffortJointInterface</hardwareInterface>
        <mechanicalReduction>1</mechanicalReduction>
        </actuator>
    </transmission>

<!--Leg front right-->

    <link name="hipassembly_4">
	    <visual>
	      <origin rpy="0.0 0.0 0.0" xyz="0.0 0.0 0.0"/>
	      <geometry>
	            <mesh filename="package://hex/models/hexapod/meshes/leg/assembler.stl" scale="1 1 1"/>
	      </geometry>
            <material name="green">
                <color rgba="0 0.6 0 1"/>
            </material>
	    </visual>  
         <collision>
            <origin rpy="0.0 0.0 0.0" xyz="0.0 0.0 0.0"/>
	        <geometry>
	            <mesh filename="package://hex/models/hexapod/meshes/leg/assembler.stl" scale="1 1 1"/>
	        </geometry> 
        </collision>   
        <inertial>
            <mass value="2"/>
            <inertia ixx="0.04" ixy="0.0" ixz="0.0" iyy="0.17" iyz="0.0" izz="0.25"/>
        </inertial>        
    </link>

    <gazebo reference="hipassembly_4">
        <kp>1000.0</kp>
        <kd>1000.0</kd>
        <mu1>0.5</mu1>
        <mu2>0.5</mu2>
        <material>Gazebo/Green</material>
    </gazebo>

    <link name="upperleg_4">
	    <visual>
	      <origin rpy="0.0 0.0 0.0" xyz="0.0 0.0 0.0"/>
	      <geometry>
	            <mesh filename="package://hex/models/hexapod/meshes/leg/upperleg.stl" scale="0.8 1 1"/>
	      </geometry>
            <material name="orange">
                <color rgba="0.8 0.5 0 1"/>
            </material>	  
	    </visual>
         <collision>
            <origin rpy="0.0 0.0 0.0" xyz="0.0 0.0 0.0"/>
	        <geometry>
	            <mesh filename="package://hex/models/hexapod/meshes/leg/upperleg.stl" scale="0.8 1 1"/>
	        </geometry> 
        </collision>   
        <inertial>
            <mass value="2"/>
            <inertia ixx="0.04" ixy="0.0" ixz="0.0" iyy="0.17" iyz="0.0" izz="0.25"/>
        </inertial>  
    </link>

    <gazebo reference="upperleg_4">
        <kp>1000.0</kp>
        <kd>1000.0</kd>
        <mu1>0.5</mu1>
        <mu2>0.5</mu2>
        <material>Gazebo/Orange</material>
    </gazebo>

    <link name="lowerleg_4">
	    <visual>
	      <geometry>
	            <mesh filename="package://hex/models/hexapod/meshes/leg/lowerleg.stl" scale="1.4 1 1"/>
	      </geometry>
            <material name="blue">
                <color rgba="0 0 0.5 1"/>
            </material>	  
        </visual> 
         <collision>
            <origin rpy="0.0 0.0 0.0" xyz="0.0 0.0 0.0"/>
	        <geometry>
	            <mesh filename="package://hex/models/hexapod/meshes/leg/lowerleg.stl" scale="1.4 1 1"/>
	        </geometry> 
        </collision>   
        <inertial>
            <mass value="2"/>
            <inertia ixx="0.04" ixy="0.0" ixz="0.0" iyy="0.17" iyz="0.0" izz="0.25"/>
        </inertial>         
    </link>

    <gazebo reference="lowerleg_4">
        <kp>1000.0</kp>
        <kd>1000.0</kd>
        <mu1>0.5</mu1>
        <mu2>0.5</mu2>
        <material>Gazebo/Blue</material>
    </gazebo>

    <joint name="haa_joint_4" type="revolute">
        <origin xyz="0.65 -0.45 0.03" rpy="0 0 0"/>
        <parent link="base"/>
        <child  link="hipassembly_4"/>
        <limit effort="200" lower="0" upper="-2.27" velocity="1.0"/>
        <axis xyz="0 0 1"/>
    </joint>
    <joint name="hfe_joint_4" type="revolute">
        <origin xyz="0.08000 0.00000 0.00000" rpy="1.5707963705062866 0 0.0"/>
        <parent link="hipassembly_4"/>
        <child  link="upperleg_4"/>
        <limit effort="200" lower="0.3" upper="1.4" velocity="1.0"/>
        <axis xyz="0 0 1"/>
    </joint>
    <joint name="kfe_joint_4" type="revolute">
        <origin xyz="0.27000 0.0000 0.0000" rpy="0.0 0.0 0.0"/>
        <parent link="upperleg_4"/>
        <child  link="lowerleg_4"/>
        <limit effort="200" lower="-2.27" upper="-1.57" velocity="1.0"/>
        <axis xyz="0 0 1"/>
    </joint>

    <transmission name="haa_joint_4_trans">
        <type>transmission_interface/SimpleTransmission</type>
        <joint name="haa_joint_4">
            <hardwareInterface>hardware_interface/EffortJointInterface</hardwareInterface>
        </joint>
        <actuator name="haa_joint_4_Motor">
        <hardwareInterface>hardware_interface/EffortJointInterface</hardwareInterface>
        <mechanicalReduction>1</mechanicalReduction>
        </actuator>
    </transmission>

    <transmission name="hfe_joint_4_trans">
        <type>transmission_interface/SimpleTransmission</type>
        <joint name="hfe_joint_4">
            <hardwareInterface>hardware_interface/EffortJointInterface</hardwareInterface>
        </joint>
        <actuator name="hfe_joint_4_Motor">
        <hardwareInterface>hardware_interface/EffortJointInterface</hardwareInterface>
        <mechanicalReduction>1</mechanicalReduction>
        </actuator>
    </transmission>

    <transmission name="kfe_joint_4_trans">
        <type>transmission_interface/SimpleTransmission</type>
        <joint name="kfe_joint_4">
            <hardwareInterface>hardware_interface/EffortJointInterface</hardwareInterface>
        </joint>
        <actuator name="kfe_joint_4_Motor">
        <hardwareInterface>hardware_interface/EffortJointInterface</hardwareInterface>
        <mechanicalReduction>1</mechanicalReduction>
        </actuator>
    </transmission>


<!--Leg middle right-->

    <link name="hipassembly_5">
	    <visual>
	      <origin rpy="0.0 0.0 0.0" xyz="0.0 0.0 0.0"/>
	      <geometry>
	            <mesh filename="package://hex/models/hexapod/meshes/leg/assembler.stl" scale="1 1 1"/>
	      </geometry>
            <material name="green">
                <color rgba="0 0.6 0 1"/>
            </material>
	    </visual>    
         <collision>
            <origin rpy="0.0 0.0 0.0" xyz="0.0 0.0 0.0"/>
	        <geometry>
	            <mesh filename="package://hex/models/hexapod/meshes/leg/assembler.stl" scale="1 1 1"/>
	        </geometry> 
        </collision>   
        <inertial>
            <mass value="2"/>
            <inertia ixx="0.04" ixy="0.0" ixz="0.0" iyy="0.17" iyz="0.0" izz="0.25"/>
        </inertial>     
    </link>
    <gazebo reference="hipassembly_5">
        <kp>1000.0</kp>
        <kd>1000.0</kd>
        <mu1>0.5</mu1>
        <mu2>0.5</mu2>
        <material>Gazebo/Green</material>
    </gazebo>

    <link name="upperleg_5">
	    <visual>
	      <origin rpy="0.0 0.0 0.0" xyz="0.0 0.0 0.0"/>
	      <geometry>
	            <mesh filename="package://hex/models/hexapod/meshes/leg/upperleg.stl" scale="0.8 1 1"/>
	      </geometry>
            <material name="orange">
                <color rgba="0.8 0.5 0 1"/>
            </material>	  
	    </visual>
         <collision>
            <origin rpy="0.0 0.0 0.0" xyz="0.0 0.0 0.0"/>
	        <geometry>
	            <mesh filename="package://hex/models/hexapod/meshes/leg/upperleg.stl" scale="0.8 1 1"/>
	        </geometry> 
        </collision>   
        <inertial>
            <mass value="2"/>
            <inertia ixx="0.04" ixy="0.0" ixz="0.0" iyy="0.17" iyz="0.0" izz="0.25"/>
        </inertial>   
    </link>
    <gazebo reference="upperleg_5">
        <kp>1000.0</kp>
        <kd>1000.0</kd>
        <mu1>0.5</mu1>
        <mu2>0.5</mu2>
        <material>Gazebo/Orange</material>
    </gazebo>

    <link name="lowerleg_5">
	    <visual>
	      <geometry>
	            <mesh filename="package://hex/models/hexapod/meshes/leg/lowerleg.stl" scale="1.4 1 1"/>
	      </geometry>
            <material name="blue">
                <color rgba="0 0 0.5 1"/>
            </material>	  
        </visual>    
         <collision>
            <origin rpy="0.0 0.0 0.0" xyz="0.0 0.0 0.0"/>
	        <geometry>
	            <mesh filename="package://hex/models/hexapod/meshes/leg/lowerleg.stl" scale="1.4 1 1"/>
	        </geometry> 
        </collision>   
        <inertial>
            <mass value="2"/>
            <inertia ixx="0.04" ixy="0.0" ixz="0.0" iyy="0.17" iyz="0.0" izz="0.25"/>
        </inertial>      
    </link>
    
    <gazebo reference="lowerleg_5">
        <kp>1000.0</kp>
        <kd>1000.0</kd>
        <mu1>0.5</mu1>
        <mu2>0.5</mu2>
        <material>Gazebo/Blue</material>
    </gazebo>


    <joint name="haa_joint_5" type="revolute">
        <origin xyz="0 -0.45 0.03" rpy="0 0 0"/>
        <parent link="base"/>
        <child  link="hipassembly_5"/>
        <limit effort="200" lower="-2.27" upper="-0.707" velocity="1.0"/>
        <axis xyz="0 0 1"/>

    </joint>
    <joint name="hfe_joint_5" type="revolute">
        <origin xyz="0.08000 0.00000 0.00000" rpy="1.5707963705062866 0 0.0"/>
        <parent link="hipassembly_5"/>
        <child  link="upperleg_5"/>
        <limit effort="200" lower="0.3" upper="1.4" velocity="1.0"/>
        <axis xyz="0 0 1"/>
    </joint>
    <joint name="kfe_joint_5" type="revolute">
        <origin xyz="0.27000 0.0000 0.0000" rpy="0.0 0.0 0.0"/>
        <parent link="upperleg_5"/>
        <child  link="lowerleg_5"/>
        <limit effort="200" lower="-2.27" upper="-1.57" velocity="1.0"/>
        <axis xyz="0 0 1"/>
    </joint>

    <transmission name="haa_joint_5_trans">
        <type>transmission_interface/SimpleTransmission</type>
        <joint name="haa_joint_5">
            <hardwareInterface>hardware_interface/EffortJointInterface</hardwareInterface>
        </joint>
        <actuator name="haa_joint_5_Motor">
        <hardwareInterface>hardware_interface/EffortJointInterface</hardwareInterface>
        <mechanicalReduction>1</mechanicalReduction>
        </actuator>
    </transmission>

    <transmission name="hfe_joint_5_trans">
        <type>transmission_interface/SimpleTransmission</type>
        <joint name="hfe_joint_5">
            <hardwareInterface>hardware_interface/EffortJointInterface</hardwareInterface>
        </joint>
        <actuator name="hfe_joint_5_Motor">
        <hardwareInterface>hardware_interface/EffortJointInterface</hardwareInterface>
        <mechanicalReduction>1</mechanicalReduction>
        </actuator>
    </transmission>

    <transmission name="kfe_joint_5_trans">
        <type>transmission_interface/SimpleTransmission</type>
        <joint name="kfe_joint_5">
            <hardwareInterface>hardware_interface/EffortJointInterface</hardwareInterface>
        </joint>
        <actuator name="kfe_joint_5_Motor">
        <hardwareInterface>hardware_interface/EffortJointInterface</hardwareInterface>
        <mechanicalReduction>1</mechanicalReduction>
        </actuator>
    </transmission>


<!--Leg back right-->

    <link name="hipassembly_6">
	    <visual>
	      <origin rpy="0.0 0.0 0.0" xyz="0.0 0.0 0.0"/>
	      <geometry>
	            <mesh filename="package://hex/models/hexapod/meshes/leg/assembler.stl" scale="1 1 1"/>
	      </geometry>
            <material name="green">
                <color rgba="0 0.6 0 1"/>
            </material>
	    </visual> 
         <collision>
            <origin rpy="0.0 0.0 0.0" xyz="0.0 0.0 0.0"/>
	        <geometry>
	            <mesh filename="package://hex/models/hexapod/meshes/leg/assembler.stl" scale="1 1 1"/>
	        </geometry> 
        </collision>   
        <inertial>
            <mass value="2"/>
            <inertia ixx="0.04" ixy="0.0" ixz="0.0" iyy="0.17" iyz="0.0" izz="0.25"/>
        </inertial>          
    </link>

    <gazebo reference="hipassembly_6">
        <kp>1000.0</kp>
        <kd>1000.0</kd>
        <mu1>0.5</mu1>
        <mu2>0.5</mu2>
        <material>Gazebo/Green</material>
    </gazebo>

    <link name="upperleg_6">
	    <visual>
	      <origin rpy="0.0 0.0 0.0" xyz="0.0 0.0 0.0"/>
	      <geometry>
	            <mesh filename="package://hex/models/hexapod/meshes/leg/upperleg.stl" scale="0.8 1 1"/>
	      </geometry>
            <material name="orange">
                <color rgba="0.8 0.5 0 1"/>
            </material>	  
	    </visual>
         <collision>
            <origin rpy="0.0 0.0 0.0" xyz="0.0 0.0 0.0"/>
	        <geometry>
	            <mesh filename="package://hex/models/hexapod/meshes/leg/upperleg.stl" scale="0.8 1 1"/>
	        </geometry> 
        </collision>   
        <inertial>
            <mass value="2"/>
            <inertia ixx="0.04" ixy="0.0" ixz="0.0" iyy="0.17" iyz="0.0" izz="0.25"/>
        </inertial>   
    </link>

    <gazebo reference="upperleg_6">
        <kp>1000.0</kp>
        <kd>1000.0</kd>
        <mu1>0.5</mu1>
        <mu2>0.5</mu2>
        <material>Gazebo/Orange</material>
    </gazebo>


    <link name="lowerleg_6">
	    <visual>
	      <geometry>
	            <mesh filename="package://hex/models/hexapod/meshes/leg/lowerleg.stl" scale="1.4 1 1"/>
	      </geometry>
            <material name="blue">
                <color rgba="0 0 0.5 1"/>
            </material>	  
        </visual> 
         <collision>
            <origin rpy="0.0 0.0 0.0" xyz="0.0 0.0 0.0"/>
	        <geometry>
	            <mesh filename="package://hex/models/hexapod/meshes/leg/lowerleg.stl" scale="1.4 1 1"/>
	        </geometry> 
        </collision>   
        <inertial>
            <mass value="2"/>
            <inertia ixx="0.04" ixy="0.0" ixz="0.0" iyy="0.17" iyz="0.0" izz="0.25"/>
        </inertial>       
    </link>
    <gazebo reference="lowerleg_6">
        <kp>1000.0</kp>
        <kd>1000.0</kd>
        <mu1>0.5</mu1>
        <mu2>0.5</mu2>
        <material>Gazebo/Blue</material>
    </gazebo>

    <include file="$(find hex)/models/imu/imu.sdf"/>
    <link name="imu">
        <inertial>
            <mass value="0.000001"/>
            <inertia ixx="0.0" ixy="0.0" ixz="0.0" iyy="0.0" iyz="0.0" izz="0.0"/>
        </inertial>
        <visual>
            <origin xyz="0.0 0.0 0.0" rpy="0.0 0.0 0.0"/>
            <geometry>
                <box size="0.02 0.001 0.05"/>
            </geometry>
            <material name="yellow">
                <color rgba="1.0 1.0 0.0 1.0"/>
            </material>
        </visual>
        <collision>
            <origin xyz="0.0 0.0 0.0" rpy="0.0 0.0 0.0"/>
            <geometry>
                <box size="0.02 0.001 0.05"/>
            </geometry>
        </collision>
    </link>
    <joint name="imu_joint" type="fixed">
        <parent link="lowerleg_4"/>
        <child link="imu"/>
        <origin xyz="0.4 0.8 0.8" rpy="1.57 1.57 1.57"/>
    </joint>


    <joint name="haa_joint_6" type="revolute">
        <origin xyz="-0.65 -0.45 0.03" rpy="0 0 0"/>
        <parent link="base"/>
        <child  link="hipassembly_6"/>
        <limit effort="200" lower="-3.847" upper="-0.707" velocity="1.0"/>
        <axis xyz="0 0 1"/>
    </joint>
    <joint name="hfe_joint_6" type="revolute">
        <origin xyz="0.08000 0.00000 0.00000" rpy="1.5707963705062866 0 0.0"/>
        <parent link="hipassembly_6"/>
        <child  link="upperleg_6"/>
        <limit effort="200" lower="0.3" upper="0.3" velocity="1.0"/>
        <axis xyz="0 0 1"/>
    </joint>
    <joint name="kfe_joint_6" type="revolute">
        <origin xyz="0.27000 0.0000 0.0000" rpy="0.0 0.0 0.0"/>
        <parent link="upperleg_6"/>
        <child  link="lowerleg_6"/>
        <limit effort="200" lower="-2.27" upper="-1.57" velocity="1.0"/>
        <axis xyz="0 0 1"/>
    </joint>
    
    <transmission name="haa_joint_6_trans">
        <type>transmission_interface/SimpleTransmission</type>
        <joint name="haa_joint_6">
            <hardwareInterface>hardware_interface/EffortJointInterface</hardwareInterface>
        </joint>
        <actuator name="haa_joint_6_Motor">
        <hardwareInterface>hardware_interface/EffortJointInterface</hardwareInterface>
        <mechanicalReduction>1</mechanicalReduction>
        </actuator>
    </transmission>

    <transmission name="hfe_joint_6_trans">
        <type>transmission_interface/SimpleTransmission</type>
        <joint name="hfe_joint_6">
            <hardwareInterface>hardware_interface/EffortJointInterface</hardwareInterface>
        </joint>
        <actuator name="hfe_joint_6_Motor">
        <hardwareInterface>hardware_interface/EffortJointInterface</hardwareInterface>
        <mechanicalReduction>1</mechanicalReduction>
        </actuator>
    </transmission>

    <transmission name="kfe_joint_6_trans">
        <type>transmission_interface/SimpleTransmission</type>
        <joint name="kfe_joint_6">
            <hardwareInterface>hardware_interface/EffortJointInterface</hardwareInterface>
        </joint>
        <actuator name="kfe_joint_6_Motor">
        <hardwareInterface>hardware_interface/EffortJointInterface</hardwareInterface>
        <mechanicalReduction>1</mechanicalReduction>
        </actuator>
    </transmission>


</robot>