<?xml version="1.0" ?>
<!-- =================================================================================== -->
<!-- |    This document was autogenerated by xacro from hexapod.urdf.xacro             | -->
<!-- |    EDITING THIS FILE BY HAND IS NOT RECOMMENDED                                 | -->
<!-- =================================================================================== -->
<robot name="hexapod">
  <!-- Leg Parameters -->
  <material name="body">
    <color rgba="0.5 0 0.2 0.5"/>
  </material>
  <link name="cover_top">
    <visual>
      <geometry>
        <mesh filename="package://hex_description/models/hexapod/meshes/cover_top.stl" scale="0.01 0.01 0.01"/>
      </geometry>
      <origin xyz="-0.02 -0 0"/>
      <material name="body"/>
    </visual>
    <inertial>
      <mass value="0.05"/>
      <inertia ixx="0.004208333333333334" ixy="0" ixz="0" iyy="0.014833333333333337" iyz="0" izz="0.010708333333333335"/>
    </inertial>
    <collision>
      <geometry>
        <mesh filename="package://hex_description/models/hexapod/meshes/cover_top.stl" scale="0.01 0.01 0.01"/>
        <origin xyz="-0.02 -0 0"/>
      </geometry>
    </collision>
  </link>
  <joint name="body_top_cover_top_joint" type="fixed">
    <parent link="body_top"/>
    <child link="cover_top"/>
    <origin rpy="0.0 0.0 -0.05" xyz="0.0 -0.115 0.31"/>
  </joint>
  <link name="body_top">
    <visual>
      <geometry>
        <mesh filename="package://hex_description/models/hexapod/meshes/body_top.stl" scale="0.01 0.01 0.01"/>
      </geometry>
      <origin xyz="0 -0.42 0"/>
      <material name="body"/>
    </visual>
    <inertial>
      <mass value="0.2"/>
      <inertia ixx="0.016833333333333336" ixy="0" ixz="0" iyy="0.05933333333333335" iyz="0" izz="0.04283333333333334"/>
    </inertial>
    <collision>
      <geometry>
        <mesh filename="package://hex_description/models/hexapod/meshes/body_top.stl" scale="0.01 0.01 0.01"/>
        <origin xyz="0 -0.42 0"/>
      </geometry>
    </collision>
  </link>
  <joint name="body_top_body_bottom_joint" type="fixed">
    <parent link="body_bottom"/>
    <child link="body_top"/>
    <origin rpy="0.0 0.0 0.0" xyz="0.0 0.02 0"/>
  </joint>
  <link name="board_bracket">
    <visual>
      <geometry>
        <mesh filename="package://hex_description/models/hexapod/meshes/board_bracket.stl" scale="0.01 0.01 0.01"/>
      </geometry>
      <origin xyz="0 0 0"/>
      <material name="green">
        <color rgba="0 0.2 0 0.5"/>
      </material>
    </visual>
    <inertial>
      <mass value="0.3"/>
      <inertia ixx="0.009089999999999999" ixy="0" ixz="0" iyy="0.03925000000000001" iyz="0" izz="0.030340000000000006"/>
    </inertial>
    <collision>
      <geometry>
        <mesh filename="package://hex_description/models/hexapod/meshes/board_bracket.stl" scale="0.01 0.01 0.01"/>
        <origin xyz="0 0 0"/>
      </geometry>
    </collision>
  </link>
  <joint name="base_bottom_bracket_board" type="fixed">
    <parent link="body_bottom"/>
    <child link="board_bracket"/>
    <origin rpy="0.0 0.0 0.0" xyz="0 -0.03 0"/>
  </joint>
  <link name="body_bottom">
    <visual>
      <geometry>
        <mesh filename="package://hex_description/models/hexapod/meshes/body_bottom.stl" scale="0.01 0.01 0.01"/>
      </geometry>
      <origin xyz="0.0 -0.425 0"/>
      <material name="body"/>
    </visual>
    <inertial>
      <mass value="0.2"/>
      <inertia ixx="0.016833333333333336" ixy="0" ixz="0" iyy="0.05933333333333335" iyz="0" izz="0.04283333333333334"/>
    </inertial>
    <collision>
      <geometry>
        <mesh filename="package://hex_description/models/hexapod/meshes/body_bottom.stl" scale="0.01 0.01 0.01"/>
        <origin xyz="0.0 -0.425 0"/>
      </geometry>
    </collision>
  </link>
  <link name="base_footprint"/>
  <joint name="base_footprint_base_bottom_joint" type="fixed">
    <parent link="base_footprint"/>
    <child link="body_bottom"/>
    <origin rpy="0.0 0.0 0.0" xyz="0.0 0.0 0.0"/>
  </joint>
  <material name="coxa">
    <color rgba="0.5 0 0.5 1"/>
  </material>
  <material name="femur">
    <color rgba="0.5 0 0.5 1"/>
  </material>
  <material name="tibia">
    <color rgba="0.5 0 0.5 1"/>
  </material>
  <link name="coxa_1">
    <visual>
      <geometry>
        <mesh filename="package://hex_description/models/hexapod/meshes/coxa.stl" scale="0.01 0.01 0.01"/>
      </geometry>
      <origin xyz="0 0 0"/>
      <material name="coxa"/>
    </visual>
    <inertial>
      <mass value="0.2"/>
      <inertia ixx="0.008333333333333333" ixy="0" ixz="0" iyy="0.004541666666666667" iyz="0" izz="0.004541666666666667"/>
    </inertial>
    <collision>
      <geometry>
        <mesh filename="package://hex_description/models/hexapod/meshes/coxa.stl" scale="0.01 0.01 0.01"/>
        <origin xyz="0 0 0"/>
      </geometry>
    </collision>
  </link>
  <link name="femur_1">
    <visual>
      <geometry>
        <mesh filename="package://hex_description/models/hexapod/meshes/femur.stl" scale="0.01 0.01 0.01"/>
      </geometry>
      <origin xyz="0 0 0"/>
      <material name="femur"/>
    </visual>
    <inertial>
      <mass value="0.2"/>
      <inertia ixx="0.009121666666666667" ixy="0" ixz="0" iyy="0.012015" iyz="0" izz="0.0038566666666666675"/>
    </inertial>
    <collision>
      <geometry>
        <mesh filename="package://hex_description/models/hexapod/meshes/femur.stl" scale="0.01 0.01 0.01"/>
        <origin xyz="0 0 0"/>
      </geometry>
    </collision>
  </link>
  <link name="tibia_1">
    <visual>
      <geometry>
        <mesh filename="package://hex_description/models/hexapod/meshes/tibia.stl" scale="0.01 0.01 0.01"/>
      </geometry>
      <origin xyz="0 0 0"/>
      <material name="tibia"/>
    </visual>
    <inertial>
      <mass value="0.2"/>
      <inertia ixx="0.02284833333333333" ixy="0" ixz="0" iyy="0.023541666666666666" iyz="0" izz="0.0023066666666666665"/>
    </inertial>
    <collision>
      <geometry>
        <mesh filename="package://hex_description/models/hexapod/meshes/tibia.stl" scale="0.01 0.01 0.01"/>
        <origin xyz="0 0 0"/>
      </geometry>
    </collision>
  </link>
  <joint name="base_coxa_joint_1" type="revolute">
    <parent link="body_bottom"/>
    <child link="coxa_1"/>
    <origin rpy="0 0 2.44" xyz="0.7 0.435 0.05"/>
    <limit effort="50.0" lower="-0.707" upper="0.707" velocity="1"/>
    <axis xyz="0 0 1"/>
    <dynamics damping="60.0" friction="4.0"/>
  </joint>
  <joint name="coxa_femur_joint_1" type="revolute">
    <parent link="coxa_1"/>
    <child link="femur_1"/>
    <origin rpy="0.0 0.0 0.0" xyz="0.09 -0.345 -0.04"/>
    <limit effort="200.0" lower="-0.707" upper="0.707" velocity="1"/>
    <axis xyz="1 0 0"/>
    <dynamics damping="60.0" friction="4.0"/>
  </joint>
  <joint name="femur_tibia_joint_1" type="revolute">
    <parent link="femur_1"/>
    <child link="tibia_1"/>
    <origin rpy="0 0.0 0.0" xyz="-0.035 -0.555 0.0"/>
    <limit effort="200.0" lower="0.707" upper="2.3" velocity="1"/>
    <axis xyz="1 0 0"/>
    <dynamics damping="0.7" friction="0.1"/>
  </joint>
  <transmission name="tran1">
    <type>transmission_interface/SimpleTransmission</type>
    <joint name="base_coxa_joint_1">
      <hardwareInterface>hardware_interface/EffortJointInterface</hardwareInterface>
    </joint>
    <actuator name="motor1">
      <hardwareInterface>hardware_interface/EffortJointInterface</hardwareInterface>
      <mechanicalReduction>1</mechanicalReduction>
    </actuator>
  </transmission>
  <transmission name="tran2">
    <type>transmission_interface/SimpleTransmission</type>
    <joint name="coxa_femur_joint_1">
      <hardwareInterface>hardware_interface/EffortJointInterface</hardwareInterface>
    </joint>
    <actuator name="motor2">
      <hardwareInterface>hardware_interface/EffortJointInterface</hardwareInterface>
      <mechanicalReduction>1</mechanicalReduction>
    </actuator>
  </transmission>
  <transmission name="tran3">
    <type>transmission_interface/SimpleTransmission</type>
    <joint name="femur_tibia_joint_1">
      <hardwareInterface>hardware_interface/EffortJointInterface</hardwareInterface>
    </joint>
    <actuator name="motor3">
      <hardwareInterface>hardware_interface/EffortJointInterface</hardwareInterface>
      <mechanicalReduction>1</mechanicalReduction>
    </actuator>
  </transmission>
  <gazebo reference="base">
    <kp>1000000.0</kp>
    <kd>100.0</kd>
    <mu1>0.5</mu1>
    <mu2>0.5</mu2>
    <maxVel>1.0</maxVel>
    <minDepth>0.001</minDepth>
    <material>Gazebo/Red</material>
  </gazebo>
  <gazebo reference="coxa_1">
    <mu1>0.1</mu1>
    <mu2>0.1</mu2>
    <kp>500000.0</kp>
    <kd>10.0</kd>
    <minDepth>0.001</minDepth>
    <maxVel>0.1</maxVel>
    <fdir1>1 0 0</fdir1>
    <material>Gazebo/Green</material>
  </gazebo>
  <gazebo reference="femur_1">
    <mu1>0.1</mu1>
    <mu2>0.1</mu2>
    <kp>500000.0</kp>
    <kd>10.0</kd>
    <minDepth>0.001</minDepth>
    <maxVel>0.1</maxVel>
    <fdir1>1 0 0</fdir1>
    <material>Gazebo/Orange</material>
  </gazebo>
  <gazebo reference="tibia_1">
    <mu1>0.1</mu1>
    <mu2>0.1</mu2>
    <kp>500000.0</kp>
    <kd>10.0</kd>
    <minDepth>0.001</minDepth>
    <maxVel>0.1</maxVel>
    <fdir1>1 0 0</fdir1>
    <material>Gazebo/Blue</material>
  </gazebo>
  <link name="coxa_2">
    <visual>
      <geometry>
        <mesh filename="package://hex_description/models/hexapod/meshes/coxa.stl" scale="0.01 0.01 0.01"/>
      </geometry>
      <origin xyz="0 0 0"/>
      <material name="coxa"/>
    </visual>
    <inertial>
      <mass value="0.2"/>
      <inertia ixx="0.008333333333333333" ixy="0" ixz="0" iyy="0.004541666666666667" iyz="0" izz="0.004541666666666667"/>
    </inertial>
    <collision>
      <geometry>
        <mesh filename="package://hex_description/models/hexapod/meshes/coxa.stl" scale="0.01 0.01 0.01"/>
        <origin xyz="0 0 0"/>
      </geometry>
    </collision>
  </link>
  <link name="femur_2">
    <visual>
      <geometry>
        <mesh filename="package://hex_description/models/hexapod/meshes/femur.stl" scale="0.01 0.01 0.01"/>
      </geometry>
      <origin xyz="0 0 0"/>
      <material name="femur"/>
    </visual>
    <inertial>
      <mass value="0.2"/>
      <inertia ixx="0.009121666666666667" ixy="0" ixz="0" iyy="0.012015" iyz="0" izz="0.0038566666666666675"/>
    </inertial>
    <collision>
      <geometry>
        <mesh filename="package://hex_description/models/hexapod/meshes/femur.stl" scale="0.01 0.01 0.01"/>
        <origin xyz="0 0 0"/>
      </geometry>
    </collision>
  </link>
  <link name="tibia_2">
    <visual>
      <geometry>
        <mesh filename="package://hex_description/models/hexapod/meshes/tibia.stl" scale="0.01 0.01 0.01"/>
      </geometry>
      <origin xyz="0 0 0"/>
      <material name="tibia"/>
    </visual>
    <inertial>
      <mass value="0.2"/>
      <inertia ixx="0.02284833333333333" ixy="0" ixz="0" iyy="0.023541666666666666" iyz="0" izz="0.0023066666666666665"/>
    </inertial>
    <collision>
      <geometry>
        <mesh filename="package://hex_description/models/hexapod/meshes/tibia.stl" scale="0.01 0.01 0.01"/>
        <origin xyz="0 0 0"/>
      </geometry>
    </collision>
  </link>
  <joint name="base_coxa_joint_2" type="revolute">
    <parent link="body_bottom"/>
    <child link="coxa_2"/>
    <origin rpy="0 0 3.14" xyz="-0.03 0.59 0.05"/>
    <limit effort="50.0" lower="-0.707" upper="0.707" velocity="1"/>
    <axis xyz="0 0 1"/>
    <dynamics damping="60.0" friction="4.0"/>
  </joint>
  <joint name="coxa_femur_joint_2" type="revolute">
    <parent link="coxa_2"/>
    <child link="femur_2"/>
    <origin rpy="0.0 0.0 0.0" xyz="0.09 -0.345 -0.04"/>
    <limit effort="200.0" lower="-0.707" upper="0.707" velocity="1"/>
    <axis xyz="1 0 0"/>
    <dynamics damping="60.0" friction="4.0"/>
  </joint>
  <joint name="femur_tibia_joint_2" type="revolute">
    <parent link="femur_2"/>
    <child link="tibia_2"/>
    <origin rpy="0 0.0 0.0" xyz="-0.035 -0.555 0.0"/>
    <limit effort="200.0" lower="0.707" upper="2.3" velocity="1"/>
    <axis xyz="1 0 0"/>
    <dynamics damping="0.7" friction="0.1"/>
  </joint>
  <transmission name="tran1">
    <type>transmission_interface/SimpleTransmission</type>
    <joint name="base_coxa_joint_2">
      <hardwareInterface>hardware_interface/EffortJointInterface</hardwareInterface>
    </joint>
    <actuator name="motor1">
      <hardwareInterface>hardware_interface/EffortJointInterface</hardwareInterface>
      <mechanicalReduction>1</mechanicalReduction>
    </actuator>
  </transmission>
  <transmission name="tran2">
    <type>transmission_interface/SimpleTransmission</type>
    <joint name="coxa_femur_joint_2">
      <hardwareInterface>hardware_interface/EffortJointInterface</hardwareInterface>
    </joint>
    <actuator name="motor2">
      <hardwareInterface>hardware_interface/EffortJointInterface</hardwareInterface>
      <mechanicalReduction>1</mechanicalReduction>
    </actuator>
  </transmission>
  <transmission name="tran3">
    <type>transmission_interface/SimpleTransmission</type>
    <joint name="femur_tibia_joint_2">
      <hardwareInterface>hardware_interface/EffortJointInterface</hardwareInterface>
    </joint>
    <actuator name="motor3">
      <hardwareInterface>hardware_interface/EffortJointInterface</hardwareInterface>
      <mechanicalReduction>1</mechanicalReduction>
    </actuator>
  </transmission>
  <gazebo reference="base">
    <kp>1000000.0</kp>
    <kd>100.0</kd>
    <mu1>0.5</mu1>
    <mu2>0.5</mu2>
    <maxVel>1.0</maxVel>
    <minDepth>0.001</minDepth>
    <material>Gazebo/Red</material>
  </gazebo>
  <gazebo reference="coxa_2">
    <mu1>0.1</mu1>
    <mu2>0.1</mu2>
    <kp>500000.0</kp>
    <kd>10.0</kd>
    <minDepth>0.001</minDepth>
    <maxVel>0.1</maxVel>
    <fdir1>1 0 0</fdir1>
    <material>Gazebo/Green</material>
  </gazebo>
  <gazebo reference="femur_2">
    <mu1>0.1</mu1>
    <mu2>0.1</mu2>
    <kp>500000.0</kp>
    <kd>10.0</kd>
    <minDepth>0.001</minDepth>
    <maxVel>0.1</maxVel>
    <fdir1>1 0 0</fdir1>
    <material>Gazebo/Orange</material>
  </gazebo>
  <gazebo reference="tibia_2">
    <mu1>0.1</mu1>
    <mu2>0.1</mu2>
    <kp>500000.0</kp>
    <kd>10.0</kd>
    <minDepth>0.001</minDepth>
    <maxVel>0.1</maxVel>
    <fdir1>1 0 0</fdir1>
    <material>Gazebo/Blue</material>
  </gazebo>
  <link name="coxa_3">
    <visual>
      <geometry>
        <mesh filename="package://hex_description/models/hexapod/meshes/coxa.stl" scale="0.01 0.01 0.01"/>
      </geometry>
      <origin xyz="0 0 0"/>
      <material name="coxa"/>
    </visual>
    <inertial>
      <mass value="0.2"/>
      <inertia ixx="0.008333333333333333" ixy="0" ixz="0" iyy="0.004541666666666667" iyz="0" izz="0.004541666666666667"/>
    </inertial>
    <collision>
      <geometry>
        <mesh filename="package://hex_description/models/hexapod/meshes/coxa.stl" scale="0.01 0.01 0.01"/>
        <origin xyz="0 0 0"/>
      </geometry>
    </collision>
  </link>
  <link name="femur_3">
    <visual>
      <geometry>
        <mesh filename="package://hex_description/models/hexapod/meshes/femur.stl" scale="0.01 0.01 0.01"/>
      </geometry>
      <origin xyz="0 0 0"/>
      <material name="femur"/>
    </visual>
    <inertial>
      <mass value="0.2"/>
      <inertia ixx="0.009121666666666667" ixy="0" ixz="0" iyy="0.012015" iyz="0" izz="0.0038566666666666675"/>
    </inertial>
    <collision>
      <geometry>
        <mesh filename="package://hex_description/models/hexapod/meshes/femur.stl" scale="0.01 0.01 0.01"/>
        <origin xyz="0 0 0"/>
      </geometry>
    </collision>
  </link>
  <link name="tibia_3">
    <visual>
      <geometry>
        <mesh filename="package://hex_description/models/hexapod/meshes/tibia.stl" scale="0.01 0.01 0.01"/>
      </geometry>
      <origin xyz="0 0 0"/>
      <material name="tibia"/>
    </visual>
    <inertial>
      <mass value="0.2"/>
      <inertia ixx="0.02284833333333333" ixy="0" ixz="0" iyy="0.023541666666666666" iyz="0" izz="0.0023066666666666665"/>
    </inertial>
    <collision>
      <geometry>
        <mesh filename="package://hex_description/models/hexapod/meshes/tibia.stl" scale="0.01 0.01 0.01"/>
        <origin xyz="0 0 0"/>
      </geometry>
    </collision>
  </link>
  <joint name="base_coxa_joint_3" type="revolute">
    <parent link="body_bottom"/>
    <child link="coxa_3"/>
    <origin rpy="0 0 3.84" xyz="-0.76 0.39 0.05"/>
    <limit effort="50.0" lower="-0.707" upper="0.707" velocity="1"/>
    <axis xyz="0 0 1"/>
    <dynamics damping="60.0" friction="4.0"/>
  </joint>
  <joint name="coxa_femur_joint_3" type="revolute">
    <parent link="coxa_3"/>
    <child link="femur_3"/>
    <origin rpy="0.0 0.0 0.0" xyz="0.09 -0.345 -0.04"/>
    <limit effort="200.0" lower="-0.707" upper="0.707" velocity="1"/>
    <axis xyz="1 0 0"/>
    <dynamics damping="60.0" friction="4.0"/>
  </joint>
  <joint name="femur_tibia_joint_3" type="revolute">
    <parent link="femur_3"/>
    <child link="tibia_3"/>
    <origin rpy="0 0.0 0.0" xyz="-0.035 -0.555 0.0"/>
    <limit effort="200.0" lower="0.707" upper="2.3" velocity="1"/>
    <axis xyz="1 0 0"/>
    <dynamics damping="0.7" friction="0.1"/>
  </joint>
  <transmission name="tran1">
    <type>transmission_interface/SimpleTransmission</type>
    <joint name="base_coxa_joint_3">
      <hardwareInterface>hardware_interface/EffortJointInterface</hardwareInterface>
    </joint>
    <actuator name="motor1">
      <hardwareInterface>hardware_interface/EffortJointInterface</hardwareInterface>
      <mechanicalReduction>1</mechanicalReduction>
    </actuator>
  </transmission>
  <transmission name="tran2">
    <type>transmission_interface/SimpleTransmission</type>
    <joint name="coxa_femur_joint_3">
      <hardwareInterface>hardware_interface/EffortJointInterface</hardwareInterface>
    </joint>
    <actuator name="motor2">
      <hardwareInterface>hardware_interface/EffortJointInterface</hardwareInterface>
      <mechanicalReduction>1</mechanicalReduction>
    </actuator>
  </transmission>
  <transmission name="tran3">
    <type>transmission_interface/SimpleTransmission</type>
    <joint name="femur_tibia_joint_3">
      <hardwareInterface>hardware_interface/EffortJointInterface</hardwareInterface>
    </joint>
    <actuator name="motor3">
      <hardwareInterface>hardware_interface/EffortJointInterface</hardwareInterface>
      <mechanicalReduction>1</mechanicalReduction>
    </actuator>
  </transmission>
  <gazebo reference="base">
    <kp>1000000.0</kp>
    <kd>100.0</kd>
    <mu1>0.5</mu1>
    <mu2>0.5</mu2>
    <maxVel>1.0</maxVel>
    <minDepth>0.001</minDepth>
    <material>Gazebo/Red</material>
  </gazebo>
  <gazebo reference="coxa_3">
    <mu1>0.1</mu1>
    <mu2>0.1</mu2>
    <kp>500000.0</kp>
    <kd>10.0</kd>
    <minDepth>0.001</minDepth>
    <maxVel>0.1</maxVel>
    <fdir1>1 0 0</fdir1>
    <material>Gazebo/Green</material>
  </gazebo>
  <gazebo reference="femur_3">
    <mu1>0.1</mu1>
    <mu2>0.1</mu2>
    <kp>500000.0</kp>
    <kd>10.0</kd>
    <minDepth>0.001</minDepth>
    <maxVel>0.1</maxVel>
    <fdir1>1 0 0</fdir1>
    <material>Gazebo/Orange</material>
  </gazebo>
  <gazebo reference="tibia_3">
    <mu1>0.1</mu1>
    <mu2>0.1</mu2>
    <kp>500000.0</kp>
    <kd>10.0</kd>
    <minDepth>0.001</minDepth>
    <maxVel>0.1</maxVel>
    <fdir1>1 0 0</fdir1>
    <material>Gazebo/Blue</material>
  </gazebo>
  <link name="coxa_4">
    <visual>
      <geometry>
        <mesh filename="package://hex_description/models/hexapod/meshes/coxa.stl" scale="0.01 0.01 0.01"/>
      </geometry>
      <origin xyz="0 0 0"/>
      <material name="coxa"/>
    </visual>
    <inertial>
      <mass value="0.2"/>
      <inertia ixx="0.008333333333333333" ixy="0" ixz="0" iyy="0.004541666666666667" iyz="0" izz="0.004541666666666667"/>
    </inertial>
    <collision>
      <geometry>
        <mesh filename="package://hex_description/models/hexapod/meshes/coxa.stl" scale="0.01 0.01 0.01"/>
        <origin xyz="0 0 0"/>
      </geometry>
    </collision>
  </link>
  <link name="femur_4">
    <visual>
      <geometry>
        <mesh filename="package://hex_description/models/hexapod/meshes/femur.stl" scale="0.01 0.01 0.01"/>
      </geometry>
      <origin xyz="0 0 0"/>
      <material name="femur"/>
    </visual>
    <inertial>
      <mass value="0.2"/>
      <inertia ixx="0.009121666666666667" ixy="0" ixz="0" iyy="0.012015" iyz="0" izz="0.0038566666666666675"/>
    </inertial>
    <collision>
      <geometry>
        <mesh filename="package://hex_description/models/hexapod/meshes/femur.stl" scale="0.01 0.01 0.01"/>
        <origin xyz="0 0 0"/>
      </geometry>
    </collision>
  </link>
  <link name="tibia_4">
    <visual>
      <geometry>
        <mesh filename="package://hex_description/models/hexapod/meshes/tibia.stl" scale="0.01 0.01 0.01"/>
      </geometry>
      <origin xyz="0 0 0"/>
      <material name="tibia"/>
    </visual>
    <inertial>
      <mass value="0.2"/>
      <inertia ixx="0.02284833333333333" ixy="0" ixz="0" iyy="0.023541666666666666" iyz="0" izz="0.0023066666666666665"/>
    </inertial>
    <collision>
      <geometry>
        <mesh filename="package://hex_description/models/hexapod/meshes/tibia.stl" scale="0.01 0.01 0.01"/>
        <origin xyz="0 0 0"/>
      </geometry>
    </collision>
  </link>
  <joint name="base_coxa_joint_4" type="revolute">
    <parent link="body_bottom"/>
    <child link="coxa_4"/>
    <origin rpy="0 0 -0.7" xyz="-0.77 -0.345 0.05"/>
    <limit effort="50.0" lower="-0.707" upper="0.707" velocity="1"/>
    <axis xyz="0 0 1"/>
    <dynamics damping="60.0" friction="4.0"/>
  </joint>
  <joint name="coxa_femur_joint_4" type="revolute">
    <parent link="coxa_4"/>
    <child link="femur_4"/>
    <origin rpy="0.0 0.0 0.0" xyz="0.09 -0.345 -0.04"/>
    <limit effort="200.0" lower="-0.707" upper="0.707" velocity="1"/>
    <axis xyz="1 0 0"/>
    <dynamics damping="60.0" friction="4.0"/>
  </joint>
  <joint name="femur_tibia_joint_4" type="revolute">
    <parent link="femur_4"/>
    <child link="tibia_4"/>
    <origin rpy="0 0.0 0.0" xyz="-0.035 -0.555 0.0"/>
    <limit effort="200.0" lower="0.707" upper="2.3" velocity="1"/>
    <axis xyz="1 0 0"/>
    <dynamics damping="0.7" friction="0.1"/>
  </joint>
  <transmission name="tran1">
    <type>transmission_interface/SimpleTransmission</type>
    <joint name="base_coxa_joint_4">
      <hardwareInterface>hardware_interface/EffortJointInterface</hardwareInterface>
    </joint>
    <actuator name="motor1">
      <hardwareInterface>hardware_interface/EffortJointInterface</hardwareInterface>
      <mechanicalReduction>1</mechanicalReduction>
    </actuator>
  </transmission>
  <transmission name="tran2">
    <type>transmission_interface/SimpleTransmission</type>
    <joint name="coxa_femur_joint_4">
      <hardwareInterface>hardware_interface/EffortJointInterface</hardwareInterface>
    </joint>
    <actuator name="motor2">
      <hardwareInterface>hardware_interface/EffortJointInterface</hardwareInterface>
      <mechanicalReduction>1</mechanicalReduction>
    </actuator>
  </transmission>
  <transmission name="tran3">
    <type>transmission_interface/SimpleTransmission</type>
    <joint name="femur_tibia_joint_4">
      <hardwareInterface>hardware_interface/EffortJointInterface</hardwareInterface>
    </joint>
    <actuator name="motor3">
      <hardwareInterface>hardware_interface/EffortJointInterface</hardwareInterface>
      <mechanicalReduction>1</mechanicalReduction>
    </actuator>
  </transmission>
  <gazebo reference="base">
    <kp>1000000.0</kp>
    <kd>100.0</kd>
    <mu1>0.5</mu1>
    <mu2>0.5</mu2>
    <maxVel>1.0</maxVel>
    <minDepth>0.001</minDepth>
    <material>Gazebo/Red</material>
  </gazebo>
  <gazebo reference="coxa_4">
    <mu1>0.1</mu1>
    <mu2>0.1</mu2>
    <kp>500000.0</kp>
    <kd>10.0</kd>
    <minDepth>0.001</minDepth>
    <maxVel>0.1</maxVel>
    <fdir1>1 0 0</fdir1>
    <material>Gazebo/Green</material>
  </gazebo>
  <gazebo reference="femur_4">
    <mu1>0.1</mu1>
    <mu2>0.1</mu2>
    <kp>500000.0</kp>
    <kd>10.0</kd>
    <minDepth>0.001</minDepth>
    <maxVel>0.1</maxVel>
    <fdir1>1 0 0</fdir1>
    <material>Gazebo/Orange</material>
  </gazebo>
  <gazebo reference="tibia_4">
    <mu1>0.1</mu1>
    <mu2>0.1</mu2>
    <kp>500000.0</kp>
    <kd>10.0</kd>
    <minDepth>0.001</minDepth>
    <maxVel>0.1</maxVel>
    <fdir1>1 0 0</fdir1>
    <material>Gazebo/Blue</material>
  </gazebo>
  <link name="coxa_5">
    <visual>
      <geometry>
        <mesh filename="package://hex_description/models/hexapod/meshes/coxa.stl" scale="0.01 0.01 0.01"/>
      </geometry>
      <origin xyz="0 0 0"/>
      <material name="coxa"/>
    </visual>
    <inertial>
      <mass value="0.2"/>
      <inertia ixx="0.008333333333333333" ixy="0" ixz="0" iyy="0.004541666666666667" iyz="0" izz="0.004541666666666667"/>
    </inertial>
    <collision>
      <geometry>
        <mesh filename="package://hex_description/models/hexapod/meshes/coxa.stl" scale="0.01 0.01 0.01"/>
        <origin xyz="0 0 0"/>
      </geometry>
    </collision>
  </link>
  <link name="femur_5">
    <visual>
      <geometry>
        <mesh filename="package://hex_description/models/hexapod/meshes/femur.stl" scale="0.01 0.01 0.01"/>
      </geometry>
      <origin xyz="0 0 0"/>
      <material name="femur"/>
    </visual>
    <inertial>
      <mass value="0.2"/>
      <inertia ixx="0.009121666666666667" ixy="0" ixz="0" iyy="0.012015" iyz="0" izz="0.0038566666666666675"/>
    </inertial>
    <collision>
      <geometry>
        <mesh filename="package://hex_description/models/hexapod/meshes/femur.stl" scale="0.01 0.01 0.01"/>
        <origin xyz="0 0 0"/>
      </geometry>
    </collision>
  </link>
  <link name="tibia_5">
    <visual>
      <geometry>
        <mesh filename="package://hex_description/models/hexapod/meshes/tibia.stl" scale="0.01 0.01 0.01"/>
      </geometry>
      <origin xyz="0 0 0"/>
      <material name="tibia"/>
    </visual>
    <inertial>
      <mass value="0.2"/>
      <inertia ixx="0.02284833333333333" ixy="0" ixz="0" iyy="0.023541666666666666" iyz="0" izz="0.0023066666666666665"/>
    </inertial>
    <collision>
      <geometry>
        <mesh filename="package://hex_description/models/hexapod/meshes/tibia.stl" scale="0.01 0.01 0.01"/>
        <origin xyz="0 0 0"/>
      </geometry>
    </collision>
  </link>
  <joint name="base_coxa_joint_5" type="revolute">
    <parent link="body_bottom"/>
    <child link="coxa_5"/>
    <origin rpy="0 0 0" xyz="-0.054 -0.565 0.05"/>
    <limit effort="50.0" lower="-0.707" upper="0.707" velocity="1"/>
    <axis xyz="0 0 1"/>
    <dynamics damping="60.0" friction="4.0"/>
  </joint>
  <joint name="coxa_femur_joint_5" type="revolute">
    <parent link="coxa_5"/>
    <child link="femur_5"/>
    <origin rpy="0.0 0.0 0.0" xyz="0.09 -0.345 -0.04"/>
    <limit effort="200.0" lower="-0.707" upper="0.707" velocity="1"/>
    <axis xyz="1 0 0"/>
    <dynamics damping="60.0" friction="4.0"/>
  </joint>
  <joint name="femur_tibia_joint_5" type="revolute">
    <parent link="femur_5"/>
    <child link="tibia_5"/>
    <origin rpy="0 0.0 0.0" xyz="-0.035 -0.555 0.0"/>
    <limit effort="200.0" lower="0.707" upper="2.3" velocity="1"/>
    <axis xyz="1 0 0"/>
    <dynamics damping="0.7" friction="0.1"/>
  </joint>
  <transmission name="tran1">
    <type>transmission_interface/SimpleTransmission</type>
    <joint name="base_coxa_joint_5">
      <hardwareInterface>hardware_interface/EffortJointInterface</hardwareInterface>
    </joint>
    <actuator name="motor1">
      <hardwareInterface>hardware_interface/EffortJointInterface</hardwareInterface>
      <mechanicalReduction>1</mechanicalReduction>
    </actuator>
  </transmission>
  <transmission name="tran2">
    <type>transmission_interface/SimpleTransmission</type>
    <joint name="coxa_femur_joint_5">
      <hardwareInterface>hardware_interface/EffortJointInterface</hardwareInterface>
    </joint>
    <actuator name="motor2">
      <hardwareInterface>hardware_interface/EffortJointInterface</hardwareInterface>
      <mechanicalReduction>1</mechanicalReduction>
    </actuator>
  </transmission>
  <transmission name="tran3">
    <type>transmission_interface/SimpleTransmission</type>
    <joint name="femur_tibia_joint_5">
      <hardwareInterface>hardware_interface/EffortJointInterface</hardwareInterface>
    </joint>
    <actuator name="motor3">
      <hardwareInterface>hardware_interface/EffortJointInterface</hardwareInterface>
      <mechanicalReduction>1</mechanicalReduction>
    </actuator>
  </transmission>
  <gazebo reference="base">
    <kp>1000000.0</kp>
    <kd>100.0</kd>
    <mu1>0.5</mu1>
    <mu2>0.5</mu2>
    <maxVel>1.0</maxVel>
    <minDepth>0.001</minDepth>
    <material>Gazebo/Red</material>
  </gazebo>
  <gazebo reference="coxa_5">
    <mu1>0.1</mu1>
    <mu2>0.1</mu2>
    <kp>500000.0</kp>
    <kd>10.0</kd>
    <minDepth>0.001</minDepth>
    <maxVel>0.1</maxVel>
    <fdir1>1 0 0</fdir1>
    <material>Gazebo/Green</material>
  </gazebo>
  <gazebo reference="femur_5">
    <mu1>0.1</mu1>
    <mu2>0.1</mu2>
    <kp>500000.0</kp>
    <kd>10.0</kd>
    <minDepth>0.001</minDepth>
    <maxVel>0.1</maxVel>
    <fdir1>1 0 0</fdir1>
    <material>Gazebo/Orange</material>
  </gazebo>
  <gazebo reference="tibia_5">
    <mu1>0.1</mu1>
    <mu2>0.1</mu2>
    <kp>500000.0</kp>
    <kd>10.0</kd>
    <minDepth>0.001</minDepth>
    <maxVel>0.1</maxVel>
    <fdir1>1 0 0</fdir1>
    <material>Gazebo/Blue</material>
  </gazebo>
  <link name="coxa_6">
    <visual>
      <geometry>
        <mesh filename="package://hex_description/models/hexapod/meshes/coxa.stl" scale="0.01 0.01 0.01"/>
      </geometry>
      <origin xyz="0 0 0"/>
      <material name="coxa"/>
    </visual>
    <inertial>
      <mass value="0.2"/>
      <inertia ixx="0.008333333333333333" ixy="0" ixz="0" iyy="0.004541666666666667" iyz="0" izz="0.004541666666666667"/>
    </inertial>
    <collision>
      <geometry>
        <mesh filename="package://hex_description/models/hexapod/meshes/coxa.stl" scale="0.01 0.01 0.01"/>
        <origin xyz="0 0 0"/>
      </geometry>
    </collision>
  </link>
  <link name="femur_6">
    <visual>
      <geometry>
        <mesh filename="package://hex_description/models/hexapod/meshes/femur.stl" scale="0.01 0.01 0.01"/>
      </geometry>
      <origin xyz="0 0 0"/>
      <material name="femur"/>
    </visual>
    <inertial>
      <mass value="0.2"/>
      <inertia ixx="0.009121666666666667" ixy="0" ixz="0" iyy="0.012015" iyz="0" izz="0.0038566666666666675"/>
    </inertial>
    <collision>
      <geometry>
        <mesh filename="package://hex_description/models/hexapod/meshes/femur.stl" scale="0.01 0.01 0.01"/>
        <origin xyz="0 0 0"/>
      </geometry>
    </collision>
  </link>
  <link name="tibia_6">
    <visual>
      <geometry>
        <mesh filename="package://hex_description/models/hexapod/meshes/tibia.stl" scale="0.01 0.01 0.01"/>
      </geometry>
      <origin xyz="0 0 0"/>
      <material name="tibia"/>
    </visual>
    <inertial>
      <mass value="0.2"/>
      <inertia ixx="0.02284833333333333" ixy="0" ixz="0" iyy="0.023541666666666666" iyz="0" izz="0.0023066666666666665"/>
    </inertial>
    <collision>
      <geometry>
        <mesh filename="package://hex_description/models/hexapod/meshes/tibia.stl" scale="0.01 0.01 0.01"/>
        <origin xyz="0 0 0"/>
      </geometry>
    </collision>
  </link>
  <joint name="base_coxa_joint_6" type="revolute">
    <parent link="body_bottom"/>
    <child link="coxa_6"/>
    <origin rpy="0 0 0.7" xyz="0.69 -0.435 0.05"/>
    <limit effort="50.0" lower="-0.707" upper="0.707" velocity="1"/>
    <axis xyz="0 0 1"/>
    <dynamics damping="60.0" friction="4.0"/>
  </joint>
  <joint name="coxa_femur_joint_6" type="revolute">
    <parent link="coxa_6"/>
    <child link="femur_6"/>
    <origin rpy="0.0 0.0 0.0" xyz="0.09 -0.345 -0.04"/>
    <limit effort="200.0" lower="-0.707" upper="0.707" velocity="1"/>
    <axis xyz="1 0 0"/>
    <dynamics damping="60.0" friction="4.0"/>
  </joint>
  <joint name="femur_tibia_joint_6" type="revolute">
    <parent link="femur_6"/>
    <child link="tibia_6"/>
    <origin rpy="0 0.0 0.0" xyz="-0.035 -0.555 0.0"/>
    <limit effort="200.0" lower="0.707" upper="2.3" velocity="1"/>
    <axis xyz="1 0 0"/>
    <dynamics damping="0.7" friction="0.1"/>
  </joint>
  <transmission name="tran1">
    <type>transmission_interface/SimpleTransmission</type>
    <joint name="base_coxa_joint_6">
      <hardwareInterface>hardware_interface/EffortJointInterface</hardwareInterface>
    </joint>
    <actuator name="motor1">
      <hardwareInterface>hardware_interface/EffortJointInterface</hardwareInterface>
      <mechanicalReduction>1</mechanicalReduction>
    </actuator>
  </transmission>
  <transmission name="tran2">
    <type>transmission_interface/SimpleTransmission</type>
    <joint name="coxa_femur_joint_6">
      <hardwareInterface>hardware_interface/EffortJointInterface</hardwareInterface>
    </joint>
    <actuator name="motor2">
      <hardwareInterface>hardware_interface/EffortJointInterface</hardwareInterface>
      <mechanicalReduction>1</mechanicalReduction>
    </actuator>
  </transmission>
  <transmission name="tran3">
    <type>transmission_interface/SimpleTransmission</type>
    <joint name="femur_tibia_joint_6">
      <hardwareInterface>hardware_interface/EffortJointInterface</hardwareInterface>
    </joint>
    <actuator name="motor3">
      <hardwareInterface>hardware_interface/EffortJointInterface</hardwareInterface>
      <mechanicalReduction>1</mechanicalReduction>
    </actuator>
  </transmission>
  <gazebo reference="base">
    <kp>1000000.0</kp>
    <kd>100.0</kd>
    <mu1>0.5</mu1>
    <mu2>0.5</mu2>
    <maxVel>1.0</maxVel>
    <minDepth>0.001</minDepth>
    <material>Gazebo/Red</material>
  </gazebo>
  <gazebo reference="coxa_6">
    <mu1>0.1</mu1>
    <mu2>0.1</mu2>
    <kp>500000.0</kp>
    <kd>10.0</kd>
    <minDepth>0.001</minDepth>
    <maxVel>0.1</maxVel>
    <fdir1>1 0 0</fdir1>
    <material>Gazebo/Green</material>
  </gazebo>
  <gazebo reference="femur_6">
    <mu1>0.1</mu1>
    <mu2>0.1</mu2>
    <kp>500000.0</kp>
    <kd>10.0</kd>
    <minDepth>0.001</minDepth>
    <maxVel>0.1</maxVel>
    <fdir1>1 0 0</fdir1>
    <material>Gazebo/Orange</material>
  </gazebo>
  <gazebo reference="tibia_6">
    <mu1>0.1</mu1>
    <mu2>0.1</mu2>
    <kp>500000.0</kp>
    <kd>10.0</kd>
    <minDepth>0.001</minDepth>
    <maxVel>0.1</maxVel>
    <fdir1>1 0 0</fdir1>
    <material>Gazebo/Blue</material>
  </gazebo>
</robot>
