<?xml version="1.0"?>
<robot xmlns:xacro="http://www.ros.org/wiki/xacro">


    <xacro:macro name="leg" params="legnumber xyz rpy y_joint">

        <link name="coxa_${legnumber}">
            <visual>
            <geometry>
                <mesh filename="package://hex_description/models/hexapod/meshes/coxa.stl" scale="0.01 0.01 0.01"/>
            </geometry>
                <origin xyz="0 0 0" rpy="${rpy}"/>
            <material name="coxa"/>
            </visual>
            <inertial>
              <xacro:cylinder_intertia m="${coxa_mass}" r="0.5" h="0.15"/>
              <origin xyz="0 0 0" rpy="${rpy}"/>
            </inertial>
            <collision>
                <geometry>
                    <mesh filename="package://hex_description/models/hexapod/meshes/coxa.stl" scale="0.01 0.01 0.01"/>
                </geometry>
                <origin xyz="0 0 0" rpy="${rpy}"/>
            </collision> 
        </link>

        <link name="femur_${legnumber}">
            <visual>
            <geometry>
                <mesh filename="package://hex_description/models/hexapod/meshes/femur.stl" scale="0.01 0.01 0.01"/>
            </geometry>
            <origin xyz="0 0 0" rpy="1.57 1.57 3.14"/>
            <material name="femur"/>
            </visual>
            <inertial>
                 <xacro:cylinder_intertia m="${femur_mass}" r="0.5" h="0.3"/>
                 <origin xyz="0 0 0" rpy="1.57 1.57 1.57"/>
            </inertial>
            <collision>
                <geometry>
                    <mesh filename="package://hex_description/models/hexapod/meshes/femur.stl" scale="0.01 0.01 0.01"/>
                </geometry>
                <origin xyz="0 0 0" rpy="1.57 1.57 3.14"/>
            </collision> 
        </link>

        <link name="tibia_${legnumber}">
            <visual>
                <geometry>
                    <mesh filename="package://hex_description/models/hexapod/meshes/tibia.stl" scale="0.01 0.01 0.01"/>
                </geometry>
                <origin xyz="0 0 0" rpy="0 1.57 1.57"/>
                <material name="tibia"/>
            </visual>
            <inertial>
                <origin xyz="0 0 0" rpy="0 1.57 0"/>
                <xacro:cylinder_intertia m="${tibia_mass}" r="0.3" h="1.15"/>
            </inertial>
            <collision>
            <geometry>
                <mesh filename="package://hex_description/models/hexapod/meshes/tibia.stl" scale="0.01 0.01 0.01"/>
            </geometry>
            <origin xyz="0 0 0" rpy="0 1.57 1.57"/>
            </collision>
        </link>

        <link name="end_point_${legnumber}"/>

        <joint name="base_coxa_joint_${legnumber}" type="revolute">
            <parent link="body_bottom"/>
            <child link="coxa_${legnumber}"/>
            <origin rpy="0 0 ${y_joint}" xyz="${xyz}"/>
            <limit effort="${base_coxa_effort}" lower="${lower_bc}" upper="${upper_bc}" velocity="${base_coxa_velocity}"/>
            <axis xyz="0 0 1"/>
            <dynamics damping="${base_coxa_damping}" friction="${base_coxa_friction}"/>
        </joint>
         
        <joint name="coxa_femur_joint_${legnumber}" type="revolute">
            <parent link="coxa_${legnumber}"/>
            <child link="femur_${legnumber}"/>
            <origin rpy="-1.57 3.14 -1.57" xyz="-0.09 0.345 -0.04"/>
            <limit effort="${coxa_femur_effort}" lower="${lower_cf}" upper="${upper_cf}" velocity="${coxa_femur_velocity}"/>
            <axis xyz="0 0 1"/>
            <dynamics damping="${coxa_femur_damping}" friction="${coxa_femur_friction}"/>
        </joint>

        <joint name="femur_tibia_joint_${legnumber}" type="revolute">
            <parent link="femur_${legnumber}"/>
            <child link="tibia_${legnumber}"/>
            <origin rpy="0 0.0 0.0" xyz="0.555 0.035 0.0"/>
            <limit effort="${femur_tibia_effort}" lower="${lower_ft}" upper="${upper_ft}" velocity="${femur_tibia_velocity}"/>
            <axis xyz="0 0 1"/>
            <dynamics damping="${femur_tibia_damping}" friction="${femur_tibia_friction}"/>
        </joint>

        <joint name="end_point_joint_${legnumber}" type="fixed">
            <parent link="tibia_${legnumber}"/>
            <child link="end_point_${legnumber}"/>
            <origin rpy="0 0.0 0.0" xyz="0.755 0 0.0"/>
        </joint>


    	<xacro:leg_transmissions legnumber="${legnumber}"/>
        <xacro:dsr_config_coeff legnumber="${legnumber}"/>
    </xacro:macro>


</robot>